Workbook

Sheet 物品
A1: zh_CN | B1: en_US | C1: class | D1: id | E1: properties | F1: tag (vanilla) | G1: tag (c:) | H1: tag (this mod) | I1: Loot | J1: Recipes | K1: 状态
A2: 舰船建造图纸 | B2: Ship Blueprint | C2: SHIP_BLUEPRINT | D2: ship_blueprint | E2: 堆叠64。不可变具体许可集合，家族由物品决定。单子类名称：大型船/中型船/小型船图纸；跨子类名称：舰船建造图纸。悬浮分类为大型/中型/小型，只列许可简称。 | F2: — | G2: — | H2: — | I2: 沉船财宝箱、埋藏宝藏；每张只含一个舰船子类的非空许可集合。 | J2: 合并：同家族2–4格各扣1张，固定产出1张许可并集图纸；有序扩展：1原图+1蓝染+7纸产8张，原图不返还。 | K2: 已实现
A3: 装备开发图纸 | B3: Equipment Blueprint | C3: EQUIPMENT_BLUEPRINT | D3: equipment_blueprint | E3: 堆叠64。不可变具体许可集合，家族由物品决定。单子类名称：武器/设备/飞机图纸；跨子类名称：装备开发图纸。悬浮说明只列可建造类型。 | F3: — | G3: — | H3: — | I3: 沉船财宝箱、埋藏宝藏；每张只含一个装备子类的非空许可集合。 | J3: 合并：同家族2–4格各扣1张，固定产出1张许可并集图纸；有序扩展：1原图+1蓝染+7纸产8张，原图不返还。 | K3: 已实现
A4: 船坞 | B4: Shipyard | C4: SHIPYARD | D4: shipyard | E4: BlockItem；堆叠1；保存取消后的缓存、燃油和浏览状态，重放不恢复任务。 | F4: — | G4: — | H4: — | I4: 生存正确工具采集保留缓存；创造不掉船坞，缓存物品散落、燃油清除。 | J4: 4钢锭、2铝锭、2燃料桶、1工作台；SAS/BCB/SAS。 | K4: 已实现
A5: 高爆弹 | B5: High-Explosive Shell | C5: HIGH_EXPLOSIVE_SHELL | D5: high_explosive_shell | E5: 堆叠64；每枚2点；固定弹种，无耐久或身份组件；点数仅制造界面显示。 | F5: — | G5: — | H5: piranport:ammunition；piranport:ammunition/shells | I5: — | J5: 弹药生产线每次加工费用见弹药生产配方页；制造点数全部通用，按缓存顺序扣料，取消返回原物。 | K5: 物品与生产已实现（0.1.103）；战斗未实现
A6: 穿甲弹 | B6: Armor-Piercing Shell | C6: ARMOR_PIERCING_SHELL | D6: armor_piercing_shell | E6: 堆叠64；每枚3点；固定弹种，无耐久或身份组件；点数仅制造界面显示。 | F6: — | G6: — | H6: piranport:ammunition；piranport:ammunition/shells | I6: — | J6: 弹药生产线每次加工费用见弹药生产配方页；制造点数全部通用，按缓存顺序扣料，取消返回原物。 | K6: 物品与生产已实现（0.1.103）；战斗未实现
A7: 防空弹 | B7: Anti-Aircraft Shell | C7: ANTI_AIRCRAFT_SHELL | D7: anti_aircraft_shell | E7: 堆叠64；每枚3点；固定弹种，无耐久或身份组件；点数仅制造界面显示。 | F7: — | G7: — | H7: piranport:ammunition；piranport:ammunition/shells | I7: — | J7: 弹药生产线每次加工费用见弹药生产配方页；制造点数全部通用，按缓存顺序扣料，取消返回原物。 | K7: 物品与生产已实现（0.1.103）；战斗未实现
A8: 深水炸弹 | B8: Depth Charge | C8: DEPTH_CHARGE | D8: depth_charge | E8: 堆叠64；每枚1点；固定弹种，无耐久或身份组件；点数仅制造界面显示。 | F8: — | G8: — | H8: piranport:ammunition；piranport:ammunition/depth_charges | I8: — | J8: 弹药生产线每次加工费用见弹药生产配方页；制造点数全部通用，按缓存顺序扣料，取消返回原物。 | K8: 物品与生产已实现（0.1.103）；战斗未实现
A9: 直航鱼雷 | B9: Straight-Running Torpedo | C9: STRAIGHT_RUNNING_TORPEDO | D9: straight_running_torpedo | E9: 堆叠64；每枚3点；固定弹种，无耐久或身份组件；点数仅制造界面显示。 | F9: — | G9: — | H9: piranport:ammunition；piranport:ammunition/torpedoes | I9: — | J9: 弹药生产线每次加工费用见弹药生产配方页；制造点数全部通用，按缓存顺序扣料，取消返回原物。 | K9: 物品与生产已实现（0.1.103）；战斗未实现
A10: 制导鱼雷 | B10: Guided Torpedo | C10: GUIDED_TORPEDO | D10: guided_torpedo | E10: 堆叠64；每枚4点；固定弹种，无耐久或身份组件；点数仅制造界面显示。 | F10: — | G10: — | H10: piranport:ammunition；piranport:ammunition/torpedoes | I10: — | J10: 弹药生产线每次加工费用见弹药生产配方页；制造点数全部通用，按缓存顺序扣料，取消返回原物。 | K10: 物品与生产已实现（0.1.103）；战斗未实现
A11: 反舰导弹 | B11: Anti-Ship Missile | C11: ANTI_SHIP_MISSILE | D11: anti_ship_missile | E11: 堆叠64；每枚8点；固定弹种，无耐久或身份组件；点数仅制造界面显示。 | F11: — | G11: — | H11: piranport:ammunition；piranport:ammunition/missiles | I11: — | J11: 弹药生产线每次加工费用见弹药生产配方页；制造点数全部通用，按缓存顺序扣料，取消返回原物。 | K11: 物品与生产已实现（0.1.103）；战斗未实现
A12: 防空导弹 | B12: Anti-Aircraft Missile | C12: ANTI_AIRCRAFT_MISSILE | D12: anti_aircraft_missile | E12: 堆叠64；每枚6点；固定弹种，无耐久或身份组件；点数仅制造界面显示。 | F12: — | G12: — | H12: piranport:ammunition；piranport:ammunition/missiles | I12: — | J12: 弹药生产线每次加工费用见弹药生产配方页；制造点数全部通用，按缓存顺序扣料，取消返回原物。 | K12: 物品与生产已实现（0.1.103）；战斗未实现
... A15: 铜粒 | B15: Copper Nugget | C15: COPPER_NUGGET | D15: copper_nugget | E15: 普通材料；堆叠64；9粒折1锭，仅弹药生产线新增铜材准入。 | F15: — | G15: c:nuggets/copper | H15: — | I15: — | J15: 1铜锭拆9铜粒；9铜粒合1原版铜锭；铜块沿用原版拆合。 | K15: 已实现（0.1.103）
A17: 规则来源 | B17: 蓝图见3.2.1，船坞见3.2.2，开发工厂见3.2.3；弹药物品与生产线分别见3.2.4两份实现方案。
A18: 状态口径 | B18: 当前0.1.105；八弹种、生产线、八配方及铜粒拆合已实现；战斗未实现。
A19: 共同行为 | B19: 图纸不绑定玩家，每项完成任务消耗1张；工厂快修每次产8个，其余产1件。扩展保留名称，合并仅同名时保留；不保存个人制造解锁。

Sheet 许可类型
A1: 家族 | B1: 子类 | C1: 许可名称 | D1: en_US | E1: 许可 ID（建议） | F1: 子类 ID（建议） | G1: 用途边界 | H1: 状态
A2: 舰船 | B2: 大型 | C2: 战列 | D2: Battleship | E2: piranport:ship/battleship | F2: piranport:ship/large | G2: 中文全称：战列舰。包含该舰种的导弹化发展。 | H2: 已实现
A3: 舰船 | B3: 大型 | C3: 战巡 | D3: Battlecruiser | E3: piranport:ship/battlecruiser | F3: piranport:ship/large | G3: 中文全称：战列巡洋舰。包含该舰种的导弹化发展。 | H3: 已实现
A4: 舰船 | B4: 大型 | C4: 航母 | D4: Aircraft Carrier | E4: piranport:ship/aircraft_carrier | F4: piranport:ship/large | G4: 中文全称：航空母舰。舰船许可，不等同于飞机许可。 | H4: 已实现
A5: 舰船 | B5: 中型 | C5: 重巡 | D5: Heavy Cruiser | E5: piranport:ship/heavy_cruiser | F5: piranport:ship/medium | G5: 中文全称：重巡洋舰。包含该舰种的导弹化发展。 | H5: 已实现
A6: 舰船 | B6: 中型 | C6: 轻母 | D6: Light Aircraft Carrier | E6: piranport:ship/light_aircraft_carrier | F6: piranport:ship/medium | G6: 中文全称：轻型航空母舰。舰船许可，不等同于飞机许可。 | H6: 已实现
A7: 舰船 | B7: 中型 | C7: 轻巡 | D7: Light Cruiser | E7: piranport:ship/light_cruiser | F7: piranport:ship/medium | G7: 中文全称：轻巡洋舰。包含该舰种的导弹化发展。 | H7: 已实现
A8: 舰船 | B8: 小型 | C8: 重炮 | D8: Monitor | E8: piranport:ship/monitor | F8: piranport:ship/small | G8: 中文全称：浅水重炮舰。舰种“重炮”，不等同于主炮武器。 | H8: 已实现
A9: 舰船 | B9: 小型 | C9: 驱逐 | D9: Destroyer | E9: piranport:ship/destroyer | F9: piranport:ship/small | G9: 中文全称：驱逐舰。包含该舰种的导弹化发展。 | H9: 已实现
A10: 舰船 | B10: 小型 | C10: 潜艇 | D10: Submarine | E10: piranport:ship/submarine | F10: piranport:ship/small | G10: 中文全称：潜水艇。潜艇、潜水艇为同义名称。 | H10: 已实现
A11: 装备 | B11: 武器 | C11: 主炮 | D11: Main Gun | E11: piranport:equipment/main_gun | F11: piranport:equipment/weapon | G11: 制造武器，不包含炮弹弹药。 | H11: 已实现
A12: 装备 | B12: 武器 | C12: 鱼雷发射器 | D12: Torpedo Launcher | E12: piranport:equipment/torpedo_launcher | F12: piranport:equipment/weapon | G12: 发射器留在武器槽中，鱼雷属于独立弹药。 | H12: 已实现
... A25: 装备 | B25: 设备 | C25: 副炮 | D25: Secondary Gun | E25: piranport:equipment/secondary_gun | F25: piranport:equipment/device | G25: 设备栏装备；原美国双联3英寸防空炮改称副炮，不限制对海／空目标。 | H25: 已实现

Sheet 配方
A1: 名称 | B1: 配方 ID（建议） | C1: 方式 | D1: 图纸槽位（格） | E1: 每格消耗（张） | F1: 纸（张） | G1: 蓝染（个） | H1: 输出（张） | I1: 净增（张） | J1: 许可处理 | K1: 排列 / 余留 | L1: 状态
A2: 2张合并 | B2: piranport:blueprint_merge | C2: 无序 | D2: 2 | E2: 1 | F2: 0 | G2: 0 | H2: 1 | I2: =H2-D2*E2 -> -1 | J2: 同家族许可取并集 | K2: 任意位置，每格扣1、固定产出1张；相同许可照常合并，无返还。 | L2: 已实现
A3: 3张合并 | B3: piranport:blueprint_merge | C3: 无序 | D3: 3 | E3: 1 | F3: 0 | G3: 0 | H3: 1 | I3: =H3-D3*E3 -> -2 | J3: 同家族许可取并集 | K3: 只统计非空格；槽内堆叠量不限，固定产出1张。 | L3: 已实现
A4: 4张合并 | B4: piranport:blueprint_merge | C4: 无序 | D4: 4 | E4: 1 | F4: 0 | G4: 0 | H4: 1 | I4: =H4-D4*E4 -> -3 | J4: 同家族许可取并集 | K4: 第5个非空格或跨家族不匹配；合并固定产出1张。 | L4: 已实现
A5: 图纸扩展 | B5: piranport:blueprint_expand | C5: 有序 | D5: 1 | E5: 1 | F5: 7 | G5: 1 | H5: 8 | I5: =H5-D5*E5 -> 7 | J5: 完整继承原图许可 | K5: 固定3×3布局见下；原图不返还，不允许旋转或上下翻转。 | L5: 已实现
A7: 原料标签 | B7: 纸：#c:papers（项目补充定义，默认含 minecraft:paper）；蓝染：#c:dyes/blue（复用现有）。允许标签内其他模组材料及七格纸混用。
A9: 扩展布局 | B9: 纸 | C9: 蓝色染料 | D9: 纸
B10: 纸 | C10: 原图纸 | D10: 纸
B11: 纸 | C11: 纸 | D11: 纸
A13: 自动复制 | B13: 支持原版合成器。每轮原图被消耗，输出8张；装置从输出回送1张到中心格后可继续，净产出7张。配方不另返还原图。

Sheet 奖励箱
A1: 来源 | B1: 战利品表 ID | C1: 0张概率 | D1: 1张概率 | E1: 2张概率 | F1: 平均数量（张） | G1: 单张内容 | H1: 两张处理 | I1: 状态
A2: 沉船财宝箱 | B2: minecraft:chests/shipwreck_treasure | C2: 0.25 | D2: 0.5 | E2: 0.25 | F2: =D2+2*E2 -> 1 | G2: 每张独立选择家族、一个子类及其非空许可集合。 | H2: 分别生成两个数量1的物品堆，即使内容相同也不主动合并。 | I2: 已实现
A3: 埋藏宝藏 | B3: minecraft:chests/buried_treasure | C3: 0 | D3: 0.5 | E3: 0.5 | F3: =D3+2*E3 -> 1.5 | G3: 每张独立选择家族、一个子类及其非空许可集合。 | H3: 分别生成两个数量1的物品堆，即使内容相同也不主动合并。 | I3: 已实现
A5: 抽取实现 | B5: 沉船：两次独立50%奖励抽取；埋藏宝藏：一次必定抽取加一次50%抽取。每次命中都单独随机许可并产生数量1的物品堆。
A6: 内容分布 | B6: 单张家族等概率，各家族三个子类等概率，许可数量1至子类总数等概率，再等概率选不重复组合。当前实现由战利品数据分层表达，数据包可调整，不属于图纸稀有度。
A7: 未投放箱 | B7: minecraft:chests/shipwreck_map、minecraft:chests/shipwreck_supply 不投放。藏宝图物品不直接发图纸；后续自建结构另行接入。
A8: 自然堆叠 | B8: 生成流程不调用合并、压缩或去重。原版后续容器整理、拾取和背包仍可自然堆叠，不为拆堆添加 UUID 或改变堆叠规则。

Sheet 进度
A1: 进度 | B1: 进度 ID（建议） | C1: 家族 | D1: 许可目标数 | E1: 累计方式 | F1: 取得判定 | G1: 不回退条件 | H1: 状态
A2: 取得所有舰船类型许可 | B2: piranport:blueprints/all_ship_types | C2: 舰船 | D2: =COUNTIFS('许可类型'!$A$2:$A$24,C2) -> 9 | E2: 9项许可分别累计；复合图纸同时满足其中多项。 | F2: 合法图纸实际进入玩家物品栏或副手；拾取、交易、合成及赠送均可。 | G2: 使用、赠送、丢失、死亡不撤回。 | H2: 已实现
A3: 取得所有装备类型许可 | B3: piranport:blueprints/all_equipment_types | C3: 装备 | D3: 15 | E3: 15项许可分别累计；复合图纸同时满足其中多项。 | F3: 只打开箱子或自动合成器产出不计给玩家，实际取得后才累计。 | G3: 跨会话保存；不要求同时持有。 | H3: 已实现
A5: 制造边界 | B5: 只保存收集成果，不授予制造权限；制造仍检查设备中实际投入的图纸。不设跨家族总体进度，不新增独立个人许可存档。
A6: 检测范围 | B6: 直接物品栏和副手，不递归扫描箱子或潜影盒。按许可做包含判定，不能用整个组件相等代替。进度撤销命令可按原版管理。

Sheet 后续设施
A1: zh_CN | B1: en_US（暂定） | C1: class | D1: id | E1: properties | F1: 图纸关系 | G1: Recipes | H1: 状态
A2: 船坞 | B2: Shipyard | C2: SHIPYARD | D2: shipyard | E2: 单工位建造全部船型，12格材料及32000 mB燃油；强化、改造标签锁定。 | F2: 开工预留1张，完工扣除；余量可取，同许可兼容堆叠可补充；不自动续建。 | G2: 4钢锭、2铝锭、2燃料桶、1工作台 | H2: 已实现
A3: 开发工厂 | B3: Development Factory | C3: DEVELOPMENT_FACTORY | D3: development_factory | E3: GUI384×252，预览96×48；单工位12格材料、16000 mB燃油；开发与锁定维修标签，橙／绿状态点。 | F3: 每任务预留并完工扣1张装备图纸；快修产8个，其余1件；不自动续做。 | G3: 4钢锭、2铝锭、1空燃料桶、1工作台、1活塞；原料燃料桶须为空。 | H3: 已实现；维修未开发
A4: 弹药生产线 | B4: Ammunition Production Line | C4: AMMUNITION_FACTORY | D4: ammunition_factory | E4: 单工位；材料和产物各8格；有限计划逐次扣料；中断完成当前一次；仅保存缓存。 | F4: 不使用图纸、动力和燃油。 | G4: 4钢锭、2铝锭、1铜锭、1活塞、1工作台；SCS/APA/SWS。 | H4: 已实现（0.1.103）

Sheet 船坞参数
A1: 参数ID | B1: 名称 | C1: 数值／规则 | D1: 单位 | E1: 说明 | F1: 状态
A2: workstations | B2: 建造工位 | C2: 1 | D2: 个 | E2: 所有船型共用任务、图纸和产物；强化、改造标签锁定 | F2: 已实现
A3: material_slots | B3: 材料缓存 | C3: 12 | D3: 格 | E3: 4列×3行，单工位统一使用 | F3: 已实现
A4: fuel_capacity | B4: 燃油容量 | C4: 32000 | D4: mB | E4: 仅接收本模组燃油，保留流体组件 | F4: 已实现
A5: blueprint_reserved | B5: 建造预留图纸 | C5: 1 | D5: 张 | E5: 其余可取；仅补充完整许可相同且可正常堆叠的图纸 | F5: 已实现
A6: blueprint_cost | B6: 每单图纸消耗 | C6: 1 | D6: 张 | E6: 完工扣除；取消不扣，补充不触发续建 | F6: 已实现
A7: ticks_per_second | B7: 标准计时 | C7: 20 | D7: tick/秒 | E7: 区块正常运行时推进；卸载和停机不补时 | F7: 已实现
A8: steel_guidance | B8: 初期钢材消耗倾向 | C8: 64 | D8: 锭/单 | E8: 建议不超过64锭，不是配方校验上限；支持块锭粒混投 | F8: 设计倾向
A9: aluminum_guidance | B9: 初期铝材消耗倾向 | C9: 64 | D9: 锭/单 | E9: 建议不超过64锭，不是配方校验上限；兼容c:标签 | F9: 设计倾向
A10: high_explosive_shell | B10: 高爆弹 | C10: 2 | D10: 点/枚 | E10: 堆叠64；八弹种完全通用；缓存顺序整枚扣除，末枚向上取整，无找零。 | F10: 已实现
A11: armor_piercing_shell | B11: 穿甲弹 | C11: 3 | D11: 点/枚 | E11: 堆叠64；八弹种完全通用；缓存顺序整枚扣除，末枚向上取整，无找零。 | F11: 已实现
A12: anti_aircraft_shell | B12: 防空弹 | C12: 3 | D12: 点/枚 | E12: 堆叠64；八弹种完全通用；缓存顺序整枚扣除，末枚向上取整，无找零。 | F12: 已实现
A13: depth_charge | B13: 深水炸弹 | C13: 1 | D13: 点/枚 | E13: 堆叠64；八弹种完全通用；缓存顺序整枚扣除，末枚向上取整，无找零。 | F13: 已实现
... A20: duration_target | B20: 首批时长目标 | C20: 180 | D20: 秒 | E20: 首批45–180秒，逐舰独立配方，不作显式上限 | F20: 设计倾向
A21: cancel_confirmation | B21: 取消确认 | C21: TRUE | D21: 开关 | E21: 默认返回；确认绑定唯一任务，过期确认不得取消新单 | F21: 已实现
A22: auto_repeat | B22: 自动续建 | C22: FALSE | D22: 开关 | E22: 不排队、不自动补充图纸、不因红石自动开工 | F22: 已实现
A23: output_pending | B23: 产物待取时开工 | C23: FALSE | D23: 开关 | E23: 建造按钮可点，仅提示先取走产物，不扣任何资源 | F23: 已实现
A24: fuel_refund_overflow | B24: 取消燃油溢出 | C24: 销毁 | D24: 规则 | E24: 尽量退回储罐，超容部分销毁；普通加油不销毁 | F24: 已实现
A25: item_overflow | B25: 找零及退款溢出 | C25: 缓存→操作者背包→掉落 | D25: 规则 | E25: 无操作者在船坞位置掉落；不因找零空间不足拒绝开工 | F25: 已实现
A26: ammo_refund | B26: 弹药退款 | C26: 原物原数 | D26: 规则 | E26: 保留开工实际扣除的种类、数量和组件 | F26: 已实现
A27: break_behavior | B27: 拆除行为 | C27: 生存保留，创造散落 | D27: 规则 | E27: 生存取消后随船坞保存；创造不掉船坞，物品散落、燃油清除 | F27: 已实现
A28: gui_fuel | B28: GUI燃油容器 | C28: 左键注入，右键取出 | D28: 规则 | E28: 鼠标携带容器，在油罐区域交互；尽量转移最大量 | F28: 已实现
A29: world_fuel | B29: 世界右键燃油容器 | C29: 未满注入，已满取出 | D29: 规则 | E29: 以点击开始状态确定单一方向；普通桶整桶；失败打开GUI | F29: 已实现
A30: top_io | B30: 顶部接口 | C30: 图纸输入输出 | D30: 规则 | E30: 唯一图纸槽；所有船型图纸均可准入；顶部不允许流体 | F30: 已实现
A31: side_io | B31: 四侧接口 | C31: 材料输入输出、优先产物 | D31: 规则 | E31: 先抽唯一产物槽，再抽材料；允许燃油双向 | F31: 已实现
A32: bottom_io | B32: 底部接口 | C32: 仅输出产物 | D32: 规则 | E32: 唯一产物槽；允许燃油双向 | F32: 已实现
A33: browse_state | B33: 浏览保存 | C33: 最后关闭窗口 | D33: 规则 | E33: 船型与舰种双向联动；窗口独立，最后关闭保存筛选、选择及滚动，不绑定UUID。 | F33: 已实现
A34: query_all | B34: 显示全部 | C34: 固定全宽勾选条 | D34: 规则 | E34: 无图纸仍可查询全部船型；不授予许可；至少4行 | F34: 已实现
A35: task_status | B35: 建造标签标记 | C35: 橙点建造、绿点待取 | D35: 规则 | E35: 空闲无点；强化、改造锁定；任务名对齐箭头，长名省略 | F35: 已实现
... A38: block_recipe | B38: 船坞合成 | C38: SAS/BCB/SAS | D38: 配方 | E38: S钢锭，A铝锭，B燃料桶，C工作台；需4钢、2铝、2燃料桶、1工作台 | F38: 已实现
A39: portable_barrel | B39: 燃料桶物品容量 | C39: 16000 | D39: mB（默认） | E39: 跟随fuelBarrelCapacity单格配置；物品能力支持组件、模拟和降容保留余量 | F39: 已实现

Sheet 船坞建造
A1: 舰船ID | B1: 舰名 | C1: 船型 | D1: 舰种 | E1: 燃油(mB) | F1: 弹药点 | G1: 钢锭 | H1: 铝锭 | I1: 建造秒 | J1: 进度tick | K1: 高爆弹等价枚数 | L1: 建造分:秒 | M1: 状态
A2: lexington_cv2 | B2: 列克星敦(CV-2) | C2: 大型 | D2: 航母 | E2: 5000 | F2: 48 | G2: 40 | H2: 48 | I2: 150 | J2: =I2*'船坞参数'!$C$7 -> 3000 | K2: =F2/'船坞参数'!$C$10 -> 24 | L2: =I2/86400 -> 0.0017361111 | M2: 已实现
A3: saratoga | B3: 萨拉托加 | C3: 大型 | D3: 航母 | E3: 5000 | F3: 48 | G3: 44 | H3: 44 | I3: 140 | J3: =I3*'船坞参数'!$C$7 -> 2800 | K3: =F3/'船坞参数'!$C$10 -> 24 | L3: =I3/86400 -> 0.0016203704 | M3: 已实现
A4: vittorio_veneto | B4: 维托里奥·维内托 | C4: 大型 | D4: 战列 | E4: 6000 | F4: 96 | G4: 64 | H4: 16 | I4: 180 | J4: =I4*'船坞参数'!$C$7 -> 3600 | K4: =F4/'船坞参数'!$C$10 -> 48 | L4: =I4/86400 -> 0.0020833333 | M4: 已实现
A5: hood | B5: 胡德 | C5: 大型 | D5: 战巡 | E5: 5000 | F5: 80 | G5: 48 | H5: 12 | I5: 165 | J5: =I5*'船坞参数'!$C$7 -> 3300 | K5: =F5/'船坞参数'!$C$10 -> 40 | L5: =I5/86400 -> 0.0019097222 | M5: 已实现
A6: quincy | B6: 昆西 | C6: 中型 | D6: 重巡 | E6: 2500 | F6: 40 | G6: 24 | H6: 8 | I6: 90 | J6: =I6*'船坞参数'!$C$7 -> 1800 | K6: =F6/'船坞参数'!$C$10 -> 20 | L6: =I6/86400 -> 0.0010416667 | M6: 已实现
A7: prinz_eugen | B7: 欧根亲王 | C7: 中型 | D7: 重巡 | E7: 3000 | F7: 48 | G7: 28 | H7: 12 | I7: 105 | J7: =I7*'船坞参数'!$C$7 -> 2100 | K7: =F7/'船坞参数'!$C$10 -> 24 | L7: =I7/86400 -> 0.0012152778 | M7: 已实现
A8: yat_sen | B8: 逸仙 | C8: 中型 | D8: 轻巡 | E8: 1500 | F8: 24 | G8: 16 | H8: 6 | I8: 60 | J8: =I8*'船坞参数'!$C$7 -> 1200 | K8: =F8/'船坞参数'!$C$10 -> 12 | L8: =I8/86400 -> 0.00069444444 | M8: 已实现
A9: glowworm | B9: 萤火虫 | C9: 小型 | D9: 驱逐 | E9: 1000 | F9: 16 | G9: 8 | H9: 4 | I9: 45 | J9: =I9*'船坞参数'!$C$7 -> 900 | K9: =F9/'船坞参数'!$C$10 -> 8 | L9: =I9/86400 -> 0.00052083333 | M9: 已实现
A10: changchun | B10: 长春 | C10: 小型 | D10: 驱逐 | E10: 2000 | F10: 48 | G10: 20 | H10: 16 | I10: 75 | J10: =I10*'船坞参数'!$C$7 -> 1500 | K10: =F10/'船坞参数'!$C$10 -> 24 | L10: =I10/86400 -> 0.00086805556 | M10: 已实现
A11: u47 | B11: U-47 | C11: 小型 | D11: 潜艇 | E11: 1000 | F11: 24 | G11: 12 | H11: 6 | I11: 60 | J11: =I11*'船坞参数'!$C$7 -> 1200 | K11: =F11/'船坞参数'!$C$10 -> 12 | L11: =I11/86400 -> 0.00069444444 | M11: 已实现
A12: — | B12: 轻母基准 | C12: 中型 | D12: 轻母 | E12: 3000 | F12: 32 | G12: 24 | H12: 24 | I12: 120 | J12: =I12*'船坞参数'!$C$7 -> 2400 | K12: =F12/'船坞参数'!$C$10 -> 16 | L12: =I12/86400 -> 0.0013888889 | M12: 基准，暂无舰船
A13: — | B13: 重炮基准 | C13: 小型 | D13: 重炮 | E13: 1500 | F13: 32 | G13: 24 | H13: 4 | I13: 75 | J13: =I13*'船坞参数'!$C$7 -> 1500 | K13: =F13/'船坞参数'!$C$10 -> 16 | L13: =I13/86400 -> 0.00086805556 | M13: 基准，暂无舰船

Sheet 设施注册
A1: 设施 | B1: 注册表／接口 | C1: 标识 | D1: 类型／入口 | E1: 参数与职责 | F1: 状态
A2: 船坞 | B2: 方块 | C2: piranport:shipyard | D2: ShipyardBlock | E2: 水平朝向；金属音；硬度4、爆炸抗性8；正确工具掉落，活塞不可推动。 | F2: 已实现
A3: 船坞 | B3: 方块实体 | C3: piranport:shipyard | D3: ShipyardBlockEntity | E3: 单工位任务、12格材料、32000 mB燃油、图纸与产物、浏览保存。 | F3: 已实现
A4: 船坞 | B4: 菜单 | C4: piranport:shipyard | D4: ShipyardMenu | E4: 同步库存与任务；打开时传方块位置与浏览状态。 | F4: 已实现
A5: 船坞 | B5: 配方类型 | C5: piranport:shipyard | D5: RecipeType<ShipyardRecipe> | E5: 十舰按具体身份匹配，费用和时间由数据包定义。 | F5: 已实现
A6: 船坞 | B6: 配方序列化器 | C6: piranport:shipyard | D6: ShipyardRecipe.Serializer | E6: 目标、燃油、弹药点、钢、铝、秒；开工冻结费用与时间。 | F6: 已实现
A7: 船坞 | B7: 数据组件 | C7: piranport:shipyard_storage | D7: CustomData | E7: 不可变保存取消后的缓存和浏览；持久化与网络编码。 | F7: 已实现
A8: 船坞 | B8: 音效 | C8: piranport:shipyard_complete | D8: SoundEvent | E8: common_craft_success素材；仅真实完工播放一次，约16格可听。 | F8: 已实现
A9: 船坞 | B9: 服务端载荷 | C9: piranport:shipyard_action | D9: ShipyardActionPayload | E9: 客户端发送意图，服务端校验菜单、距离、任务及资源。 | F9: 已实现
A10: 船坞 | B10: 客户端载荷 | C10: piranport:shipyard_sync | D10: ShipyardSyncPayload | E10: 同步任务、进度、浏览响应，不在公共路径加载渲染类。 | F10: 已实现
A11: 开发工厂 | B11: 方块 | C11: piranport:development_factory | D11: DevelopmentFactoryBlock | E11: 水平朝向；单工位，维修标签锁定；材质和外观参考船坞。 | F11: 已实现
A12: 开发工厂 | B12: 方块实体 | C12: piranport:development_factory | D12: DevelopmentFactoryBlockEntity | E12: 12格材料、16000 mB燃油；冻结产物类别、身份、数量及费用时间。 | F12: 已实现
... A29: 铜粒 | B29: 物品及拆合配方 | C29: piranport:copper_nugget | D29: 普通Item与原版有序／无序配方 | E29: 堆叠64；铜锭拆9粒，9粒合原版铜锭，兼容c:材料标签。 | F29: 已实现（0.1.103）

Sheet 开发工厂参数
A1: 参数ID | B1: 名称 | C1: 数值／规则 | D1: 单位 | E1: 说明 | F1: 状态
A2: workstations | B2: 开发工位 | C2: 1 | D2: 个 | E2: 全部武器、设备、飞机及消耗品共用一套图纸、任务、进度和产物。 | F2: 已实现
A3: material_slots | B3: 材料缓存 | C3: 12 | D3: 格 | E3: 4列×3行；接收八弹种及钢铝块、锭、粒，兼容c:标签。 | F3: 已实现
A4: fuel_capacity | B4: 燃油容量 | C4: 16000 | D4: mB | E4: 仅本mod燃油，保留组件；与船坞32000 mB分别配置。 | F4: 已实现
A5: blueprint_reserved | B5: 任务预留图纸 | C5: 1 | D5: 张 | E5: 余量可取；补充须完整许可相同且正常可堆叠；禁整槽交换。 | F5: 已实现
A6: blueprint_cost | B6: 每任务图纸消耗 | C6: 1 | D6: 张 | E6: 完工扣除，取消不扣；快修一张产8个。 | F6: 已实现
A7: ticks_per_second | B7: 标准计时 | C7: 20 | D7: tick/秒 | E7: 正常区块tick推进；关闭GUI不停止，卸载和停机不补时。 | F7: 已实现
A8: gui_width | B8: GUI宽度 | C8: 384 | D8: 像素 | E8: 外置标签不占主体，低饱和灰蓝及默认字体。 | F8: 已实现
A9: gui_height | B9: GUI高度 | C9: 252 | D9: 像素 | E9: 下半页燃油、材料和玩家物品栏保持分隔与对齐。 | F9: 已实现
A10: preview_width | B10: 预览宽度 | C10: 96 | D10: 像素 | E10: 左上横向装备预览，首阶段使用物品图标。 | F10: 已实现
A11: preview_height | B11: 预览高度 | C11: 48 | D11: 像素 | E11: 无浏览选择且无产物时为空，不显示玩家。 | F11: 已实现
A12: tabs | B12: 标签页 | C12: 装备开发／维修 | D12: 规则 | E12: 维修灰色锁定，悬浮尚未开发，无隐藏工位。 | F12: 界面已实现；维修锁定
A13: task_status | B13: 开发标签状态点 | C13: 橙点开发、绿点待取 | D13: 规则 | E13: 空闲无点，维修无点；任务名与箭头居中并显示[开发中]。 | F13: 已实现
A14: list_rows | B14: 列表最少可见行 | C14: 4 | D14: 行 | E14: 滚动条；可开发项稍浅灰底、突出按钮，受限项仍可预览。 | F14: 已实现
A15: query_all | B15: 显示全部 | C15: 固定全宽勾选条 | D15: 规则 | E15: 宽度含滚动条，右端搜索图标；无图纸可查询，不授予许可。 | F15: 已实现
A16: filters | B16: 筛选维度 | C16: 类别、文字 | D16: 规则 | E16: 类别多选取并集，与文字取交集；摘要实时显示范围、类别及关键词；无细分筛选。 | F16: 已实现
A17: search_names | B17: 文字搜索 | C17: 中英名称与别名 | D17: 规则 | E17: 忽略大小写，归一化全半角、空白和常用连接符。 | F17: 已实现
A18: search_icon | B18: 搜索图标 | C18: 有条件时改变外观 | D18: 规则 | E18: 左键打开草稿弹窗，右键清筛选并保留显示全部；返回丢弃草稿。 | F18: 已实现
A19: preview_priority | B19: 预览优先级 | C19: 主动选择、待取产物、空白 | D19: 规则 | E19: 切换浏览不改变任务；长名省略，任务后缀保持可辨。 | F19: 已实现
A20: four_resources | B20: 四资源消耗 | C20: 燃油、弹药、钢、铝 | D20: 设计规范 | E20: 首批每项均消耗一些，不增加必须全部大于零的合法性校验。 | F20: 首批已采用；不作硬校验
A21: duration_guidance | B21: 首批开发时间 | C21: 5–25 | D21: 秒 | E21: 逐项独立参数，不作为配方硬性范围或上限。 | F21: 首批已采用；不作硬校验
A22: ammo_quantum | B22: 配方弹药步长 | C22: 4 | D22: 点 | E22: 需求为4的倍数；材料值复用船坞1／2／2／4点。 | F22: 已实现
A23: metal_change | B23: 钢铝投入与找零 | C23: 先粒、锭、块 | D23: 规则 | E23: 块81粒，锭9粒；精确扣除，找零为本mod锭、粒。 | F23: 已实现
A24: ammo_consumption | B24: 弹药投入 | C24: 按缓存顺序整枚取整 | D24: 规则 | E24: 不寻找最省组合，无弹药找零，取消退原种类数量组件。 | F24: 已实现
A25: cancel_confirmation | B25: 取消确认 | C25: TRUE | D25: 开关 | E25: 紧凑居中，默认返回，确认绑定任务ID；显示预计燃油损失。 | F25: 已实现
A26: item_overflow | B26: 物品溢出 | C26: 缓存、操作者背包、掉落 | D26: 规则 | E26: 找零不阻止开工；取消返还净钢铝和原弹药。 | F26: 已实现
A27: fuel_refund_overflow | B27: 燃油退款溢出 | C27: 销毁无法容纳部分 | D27: 规则 | E27: 退原燃油及组件，超容或不相容部分销毁，确认时提示。 | F27: 已实现
A28: auto_repeat | B28: 自动续做 | C28: FALSE | D28: 开关 | E28: 每次手动开工；快修8个是单次产量，不是8个排队任务。 | F28: 已实现
A29: output_pending | B29: 待取产物时开工 | C29: FALSE | D29: 开关 | E29: 开发按钮可点但只提示取走；相同可堆叠物品也不继续做。 | F29: 已实现
A30: task_snapshot | B30: 开工快照 | C30: 目标、数量、费用、时长 | D30: 规则 | E30: 数据包刷新只影响新单，任务不绑定玩家。 | F30: 已实现
A31: durable_output | B31: 耐久装备成品 | C31: 满耐久，飞机空油 | D31: 规则 | E31: 制造燃油成本不灌入飞机油箱；不生成伪战斗参数。 | F31: 已实现
A32: quick_repair_output | B32: 快修每次产量 | C32: 8 | D32: 个 | E32: 一张图纸，800 mB、32点、8钢、8铝、5秒。 | F32: 已实现
A33: damage_control_output | B33: 损管每次产量 | C33: 1 | D33: 个 | E33: 一张图纸，800 mB、12点、6钢、4铝、15秒。 | F33: 已实现
A34: quick_repair_stack | B34: 快修物品及设备槽上限 | C34: 64 | D34: 个 | E34: 普通消耗品，无型号身份、耐久和属性修正。 | F34: 已实现
A35: damage_control_stack | B35: 损管物品及设备槽上限 | C35: 16 | D35: 个 | E35: 普通消耗品，无作战配置和主动效果；实际免死另议。 | F35: 已实现
A36: allowQuickRepairFromPlayerInventory | B36: 是否允许直接消耗玩家背包中的快修 | C36: FALSE | D36: COMMON | E36: 设备栏缺少时才按开关读取玩家快捷栏和主物品栏36格。 | F36: 配置已实现；触发未接入
A37: allowDamageControlFromPlayerInventory | B37: 是否允许直接消耗玩家背包中的损管 | C37: FALSE | D37: COMMON | E37: 两个开关独立；均默认关闭，不改变设备栏优先顺序。 | F37: 配置已实现；触发未接入
A38: consumable_lookup | B38: 未来消耗查找 | C38: 核心设备栏优先 | D38: 规则 | E38: 触发时查找，不扫副手、其他玩家、嵌套容器，不逐tick扫描。 | F38: 设计已定；触发另议
A39: consumable_effects | B39: 快修与损管用途 | C39: 缺血回复／死亡抵消 | D39: 规则 | E39: 触发阈值、回复量、免死后血量、冷却与结算顺序待设计，不写入物品。 | F39: 触发未实现
A40: break_behavior | B40: 拆除行为 | C40: 生存保留，创造散落 | D40: 规则 | E40: 先取消退款解锁；生存携带缓存，创造不掉方块、燃油清除。 | F40: 已实现
...

Sheet 装备开发
A1: 产物标识 | B1: 名称 | C1: 分组 | D1: 类别 | E1: 产物类型 | F1: 每次产量 | G1: 图纸张数 | H1: 燃油(mB) | I1: 弹药点 | J1: 钢锭 | K1: 铝锭 | L1: 开发秒 | M1: 进度tick | N1: 高爆弹等价枚数 | O1: 状态
A2: piranport:experimental_coilgun | B2: 神秘武器 | C2: 武器 | D2: 主炮 | E2: 型号 | F2: 1 | G2: 1 | H2: 800 | I2: 16 | J2: 6 | K2: 8 | L2: 20 | M2: =L2*'开发工厂参数'!$C$7 -> 400 | N2: =I2/'船坞参数'!$C$10 -> 8 | O2: 已实现
A3: piranport:british_twin_mkn5_6in | B3: 英国双联MK.N5型6英寸高平速射炮 | C3: 武器 | D3: 主炮 | E3: 型号 | F3: 1 | G3: 1 | H3: 400 | I3: 8 | J3: 6 | K3: 2 | L3: 10 | M3: =L3*'开发工厂参数'!$C$7 -> 200 | N3: =I3/'船坞参数'!$C$10 -> 4 | O3: 已实现
A4: piranport:us_triple_mk16_8in | B4: MK.16三联8英寸自动炮 | C4: 武器 | D4: 主炮 | E4: 型号 | F4: 1 | G4: 1 | H4: 600 | I4: 12 | J4: 8 | K4: 2 | L4: 15 | M4: =L4*'开发工厂参数'!$C$7 -> 300 | N4: =I4/'船坞参数'!$C$10 -> 6 | O4: 已实现
A5: piranport:us_triple_mk6_16in | B5: 美国三联16英寸炮(MK6) | C5: 武器 | D5: 主炮 | E5: 型号 | F5: 1 | G5: 1 | H5: 1000 | I5: 24 | J5: 14 | K5: 2 | L5: 25 | M5: =L5*'开发工厂参数'!$C$7 -> 500 | N5: =I5/'船坞参数'!$C$10 -> 12 | O5: 已实现
A6: piranport:italian_triple_381mm | B6: 意大利三联381毫米炮 | C6: 武器 | D6: 主炮 | E6: 型号 | F6: 1 | G6: 1 | H6: 1000 | I6: 24 | J6: 12 | K6: 4 | L6: 25 | M6: =L6*'开发工厂参数'!$C$7 -> 500 | N6: =I6/'船坞参数'!$C$10 -> 12 | O6: 已实现
A7: piranport:japanese_sextuple_610mm | B7: 日本六联61厘米鱼雷 | C7: 武器 | D7: 鱼雷发射器 | E7: 型号 | F7: 1 | G7: 1 | H7: 400 | I7: 12 | J7: 4 | K7: 2 | L7: 10 | M7: =L7*'开发工厂参数'!$C$7 -> 200 | N7: =I7/'船坞参数'!$C$10 -> 6 | O7: 已实现
A8: piranport:g7e_t10_submarine | B8: G7eT10线导鱼雷(潜艇) | C8: 武器 | D8: 鱼雷发射器 | E8: 型号 | F8: 1 | G8: 1 | H8: 500 | I8: 12 | J8: 3 | K8: 4 | L8: 15 | M8: =L8*'开发工厂参数'!$C$7 -> 300 | N8: =I8/'船坞参数'!$C$10 -> 6 | O8: 已实现
A9: piranport:hedgehog_projector | B9: 刺猬弹深弹投射器 | C9: 武器 | D9: 深弹投射器 | E9: 型号 | F9: 1 | G9: 1 | H9: 300 | I9: 8 | J9: 4 | K9: 1 | L9: 10 | M9: =L9*'开发工厂参数'!$C$7 -> 200 | N9: =I9/'船坞参数'!$C$10 -> 4 | O9: 已实现
A10: piranport:sy1_launcher | B10: 上游-1发射器 | C10: 武器 | D10: 导弹发射器 | E10: 型号 | F10: 1 | G10: 1 | H10: 800 | I10: 20 | J10: 6 | K10: 6 | L10: 20 | M10: =L10*'开发工厂参数'!$C$7 -> 400 | N10: =I10/'船坞参数'!$C$10 -> 10 | O10: 已实现
A11: piranport:mk10_launcher | B11: MK-10导弹发射器 | C11: 武器 | D11: 导弹发射器 | E11: 型号 | F11: 1 | G11: 1 | H11: 800 | I11: 20 | J11: 6 | K11: 6 | L11: 20 | M11: =L11*'开发工厂参数'!$C$7 -> 400 | N11: =I11/'船坞参数'!$C$10 -> 10 | O11: 已实现
A12: piranport:additional_armor_small | B12: 附加装甲（小型） | C12: 设备 | D12: 装甲 | E12: 型号 | F12: 1 | G12: 1 | H12: 100 | I12: 4 | J12: 4 | K12: 1 | L12: 5 | M12: =L12*'开发工厂参数'!$C$7 -> 100 | N12: =I12/'船坞参数'!$C$10 -> 2 | O12: 已实现
A13: piranport:additional_armor_medium | B13: 附加装甲（中型） | C13: 设备 | D13: 装甲 | E13: 型号 | F13: 1 | G13: 1 | H13: 200 | I13: 4 | J13: 8 | K13: 1 | L13: 10 | M13: =L13*'开发工厂参数'!$C$7 -> 200 | N13: =I13/'船坞参数'!$C$10 -> 2 | O13: 已实现
... A24: piranport:c6n_saiun | B24: 彩云 | C24: 飞机 | D24: 侦察机 | E24: 型号 | F24: 1 | G24: 1 | H24: 400 | I24: 4 | J24: 2 | K24: 6 | L24: 10 | M24: =L24*'开发工厂参数'!$C$7 -> 200 | N24: =I24/'船坞参数'!$C$10 -> 2 | O24: 已实现
A27: 费用口径 | B27: 每行是一项任务总成本，均消耗1张图纸。快修产8个，其余1个。23项已写入运行配方；数据包可调整。

Sheet 弹药生产线参数
A1: 参数ID | B1: 名称 | C1: 数值／规则 | D1: 单位 | E1: 说明 | F1: 状态
A2: workstations | B2: 加工工位 | C2: 1 | D2: 个 | E2: 一台一次运行一种弹药的有限计划，不建立异种排队。 | F2: 已实现（0.1.103）
A3: material_slots | B3: 材料缓存 | C3: 8 | D3: 格 | E3: 4列×2行；铜、钢、铝接受块锭粒，另接收原版火药；不接收铁或弹药。 | F3: 已实现（0.1.103）
A4: product_slots | B4: 产物缓存 | C4: 8 | D4: 格 | E4: 4列×2行；混放不同弹种，GUI和外部只能取，不能向产物槽插入。 | F4: 已实现（0.1.103）
A5: energy_source | B5: 动力与燃油 | C5: 无 | D5: 规则 | E5: 不要求电力、燃油、燃烧燃料，不建立隐含流体库存。 | F5: 已实现（0.1.103）
A6: blueprint_cost | B6: 图纸消耗 | C6: 0 | D6: 张 | E6: 没有图纸槽和个人解锁。 | F6: 已实现（0.1.103）
A7: ticks_per_second | B7: 标准计时 | C7: 20 | D7: tick/秒 | E7: 正常区块tick推进；关闭GUI不停止，卸载、重启不补算离线时间。 | F7: 已实现（0.1.103）
A8: gui_width | B8: 界面宽度 | C8: 348 | D8: 逻辑像素 | E8: 沿用现有制造设施背景和边框。 | F8: 已实现（0.1.103）
A9: gui_height | B9: 界面高度 | C9: 252 | D9: 逻辑像素 | E9: 无外置标签、无模型预览。 | F9: 已实现（0.1.103）
A10: default_target | B10: 首次默认弹种 | C10: high_explosive_shell | D10: 标识 | E10: 首次高爆弹，后续读取最后关闭窗口写回的一份机器浏览状态。 | F10: 已实现（0.1.103）
A11: default_demand | B11: 首次需求模式 | C11: 单次需求 | D11: 规则 | E11: 标题下方设分隔线；18逻辑像素宽的两档滑动开关切换单次需求、总需求。 | F11: 已实现（0.1.103）
A12: quantity_unit | B12: 数量输入单位 | C12: 枚 | D12: 规则 | E12: 炮弹与深弹4枚/次；鱼雷与导弹1枚/次，步长跟随单次产量；数量文字居中。 | F12: 已实现（0.1.103）
A13: quantity_correction | B13: 输入校正 | C13: 向上补足一批，再限制到材料上限 | D13: 规则 | E13: 5枚炮弹修正8枚；仅能产4枚时限制为4枚；空白、0、负数不能开工。 | F13: 已实现（0.1.103）
A14: quantity_cap | B14: 计划枚数上限 | C14: 按当前原料计算完整加工次数 | D14: 规则 | E14: 排除零费用项后计算最小可做次数，再乘产量；服务端开工重新校正。 | F14: 已实现（0.1.103）
A15: draft_vs_job | B15: 草稿与任务 | C15: 浏览可改，运行计划冻结 | D15: 规则 | E15: 缓存变化只更新上限与可开工状态，不自动改输入；提交或开工时校正。 | F15: 已实现（0.1.103）
A16: demand_follows | B16: 需求跟随 | C16: 浏览弹种、输入框和滑条 | D16: 规则 | E16: 总需求不随已完成数量或剩余次数递减；不锁定实际任务弹种。 | F16: 已实现（0.1.103）
A17: metal_display | B17: 金属显示 | C17: 只显示非0锭粒，零需求整行隐藏 | D17: 规则 | E17: 83粒显示9锭2粒；36粒显示4锭；4粒显示4粒；不换算块。 | F17: 已实现（0.1.103）
A18: charge_timing | B18: 原料扣除 | C18: 每次实际开始加工时 | D18: 规则 | E18: 只投入当前一次，不预扣后续、不锁原料；失败或模拟无副作用。 | F18: 已实现（0.1.103）
A19: metal_order | B19: 金属扣除顺序 | C19: 粒、锭、块 | D19: 规则 | E19: 同规格按缓存栏位顺序消耗；找零为原版铜锭、本模组铜粒及钢铝锭粒。 | F19: 已实现（0.1.103）
A20: change_overflow | B20: 找零溢出 | C20: 缓存、四侧相邻接收接口、掉落 | D20: 规则 | E20: 按实际剩余量处理；不占产物槽，不塞玩家背包，不因找零放不下停产。 | F20: 已实现（0.1.103）
A21: completion | B21: 批次完工 | C21: 整批入库一次 | D21: 规则 | E21: 开始前检查本批全部产物空间；入库成功后才计完成枚数与次数。 | F21: 已实现（0.1.103）
... A33: creative_removal | B33: 创造及无机器掉落移除 | C33: 缓存全散落 | D33: 规则 | E33: 不退在制材料；正常战利品已保存缓存时不能再次散落。 | F33: 已实现（0.1.103）
A34: stack_limit | B34: 机器物品堆叠 | C34: 1 | D34: 件 | E34: 带缓存与空机器均不可堆叠。 | F34: 已实现（0.1.103）
A35: tool_level | B35: 有效采集工具 | C35: 石镐及以上 | D35: 规则 | E35: 遵循原版工具标签判定。 | F35: 已实现（0.1.103）
A36: hardness | B36: 硬度 | C36: 4 | D36: 数值 | E36: 与现有制造设施一致。 | F36: 已实现（0.1.103）
A37: blast_resistance | B37: 抗爆性 | C37: 8 | D37: 数值 | E37: 活塞不可推动，水平四向，金属音效。 | F37: 已实现（0.1.103）
A38: block_recipe | B38: 机器合成 | C38: SCS/APA/SWS | D38: 有序 | E38: S钢锭4、C铜锭1、A铝锭2、P活塞1、W工作台1，产1台。 | F38: 已实现（0.1.103）
A39: copper_nugget | B39: 铜粒与拆合 | C39: 1铜锭对应9铜粒 | D39: 规则 | E39: 新增铜粒物品与两个拆合配方，原版铜块拆合不重复注册。 | F39: 已实现（0.1.103）
A40: sound | B40: 完成音效 | C40: 复用shipyard_complete | D40: 规则 | E40: 仅整份计划结束或中断收尾响一次，不逐批连续播放。 | F40: 已实现（0.1.103）
A41: right_center | B41: 右栏中心线 | C41: 296 | D41: 逻辑像素 | E41: 槽位与箭头横向居中，中心纵坐标62、94、126；顶部居中提示块锭粒可自动转换，与产量／耗时同色。 | F41: 已实现（0.1.103）
A42: right_gap | B42: 右栏上下留白 | C42: 4 | D42: 逻辑像素 | E42: 提示y26；槽组区域y40–148，输入y44–80、箭头y84–104、产物y108–144，上下及组间均4像素。 | F42: 已实现（0.1.103）
A43: ratio_spacing | B43: 进度空格 | C43: 16 / 40枚 · 第5 / 10次 | D43: 规则 | E43: 半角斜杠与中点两侧各1空格；数字紧接中文单位。 | F43: 已实现（0.1.103）
A44: recipe_scope | B44: 默认生产配方 | C44: 八弹种各一条 | D44: 规则 | E44: 由数据包覆盖，不把首批费用和2至5秒耗时设为硬上限。 | F44: 已实现（0.1.103）

Sheet 弹药生产配方
A1: 产物标识 | B1: 名称 | C1: 类别 | D1: 单次产量(枚) | E1: 铜粒 | F1: 钢粒 | G1: 铝粒 | H1: 火药(个) | I1: 耗时(秒) | J1: 单枚点数 | K1: 单批点数 | L1: 进度tick | M1: 状态 | N1: 说明
A2: piranport:high_explosive_shell | B2: 高爆弹 | C2: 炮弹 | D2: 4 | E2: 4 | F2: 4 | G2: 0 | H2: 3 | I2: 2 | J2: ='船坞参数'!C10 -> 2 | K2: =D2*J2 -> 8 | L2: =I2*'弹药生产线参数'!$C$7 -> 40 | M2: 已实现（0.1.103） | N2: 每行是一次加工的费用；零用料只在GUI隐藏，参数表保留0。
A3: piranport:armor_piercing_shell | B3: 穿甲弹 | C3: 炮弹 | D3: 4 | E3: 4 | F3: 8 | G3: 0 | H3: 2 | I3: 3 | J3: ='船坞参数'!C11 -> 3 | K3: =D3*J3 -> 12 | L3: =I3*'弹药生产线参数'!$C$7 -> 60 | M3: 已实现（0.1.103） | N3: 每行是一次加工的费用；零用料只在GUI隐藏，参数表保留0。
A4: piranport:anti_aircraft_shell | B4: 防空弹 | C4: 炮弹 | D4: 4 | E4: 4 | F4: 4 | G4: 4 | H4: 3 | I4: 3 | J4: ='船坞参数'!C12 -> 3 | K4: =D4*J4 -> 12 | L4: =I4*'弹药生产线参数'!$C$7 -> 60 | M4: 已实现（0.1.103） | N4: 每行是一次加工的费用；零用料只在GUI隐藏，参数表保留0。
A5: piranport:depth_charge | B5: 深水炸弹 | C5: 深水炸弹 | D5: 4 | E5: 0 | F5: 4 | G5: 0 | H5: 1 | I5: 2 | J5: ='船坞参数'!C13 -> 1 | K5: =D5*J5 -> 4 | L5: =I5*'弹药生产线参数'!$C$7 -> 40 | M5: 已实现（0.1.103） | N5: 每行是一次加工的费用；零用料只在GUI隐藏，参数表保留0。
A6: piranport:straight_running_torpedo | B6: 直航鱼雷 | C6: 鱼雷 | D6: 1 | E6: 2 | F6: 4 | G6: 0 | H6: 2 | I6: 2 | J6: ='船坞参数'!C14 -> 3 | K6: =D6*J6 -> 3 | L6: =I6*'弹药生产线参数'!$C$7 -> 40 | M6: 已实现（0.1.103） | N6: 每行是一次加工的费用；零用料只在GUI隐藏，参数表保留0。
A7: piranport:guided_torpedo | B7: 制导鱼雷 | C7: 鱼雷 | D7: 1 | E7: 3 | F7: 4 | G7: 2 | H7: 2 | I7: 3 | J7: ='船坞参数'!C15 -> 4 | K7: =D7*J7 -> 4 | L7: =I7*'弹药生产线参数'!$C$7 -> 60 | M7: 已实现（0.1.103） | N7: 每行是一次加工的费用；零用料只在GUI隐藏，参数表保留0。
A8: piranport:anti_ship_missile | B8: 反舰导弹 | C8: 导弹 | D8: 1 | E8: 6 | F8: 9 | G8: 6 | H8: 3 | I8: 5 | J8: ='船坞参数'!C16 -> 8 | K8: =D8*J8 -> 8 | L8: =I8*'弹药生产线参数'!$C$7 -> 100 | M8: 已实现（0.1.103） | N8: 每行是一次加工的费用；零用料只在GUI隐藏，参数表保留0。
A9: piranport:anti_aircraft_missile | B9: 防空导弹 | C9: 导弹 | D9: 1 | E9: 4 | F9: 5 | G9: 6 | H9: 3 | I9: 4 | J9: ='船坞参数'!C17 -> 6 | K9: =D9*J9 -> 6 | L9: =I9*'弹药生产线参数'!$C$7 -> 80 | M9: 已实现（0.1.103） | N9: 每行是一次加工的费用；零用料只在GUI隐藏，参数表保留0。
A11: 规则来源 | B11: 3.2.4弹药生产线实现方案，2026-10-26
A12: 状态说明 | B12: 八弹种物品、生产线和本页八项配方已实现（0.1.103）；战斗仍未实现。
